[2024-06-27T22:01:12.936+0000] {local_task_job_runner.py:120} INFO - ::group::Pre task execution logs
[2024-06-27T22:01:12.946+0000] {taskinstance.py:2076} INFO - Dependencies all met for dep_context=non-requeueable deps ti=<TaskInstance: zillow_analytics_dag.tsk_is_file_in_s3_available manual__2024-06-27T22:01:03.531556+00:00 [queued]>
[2024-06-27T22:01:12.952+0000] {taskinstance.py:2076} INFO - Dependencies all met for dep_context=requeueable deps ti=<TaskInstance: zillow_analytics_dag.tsk_is_file_in_s3_available manual__2024-06-27T22:01:03.531556+00:00 [queued]>
[2024-06-27T22:01:12.952+0000] {taskinstance.py:2306} INFO - Starting attempt 1 of 3
[2024-06-27T22:01:12.966+0000] {taskinstance.py:2330} INFO - Executing <Task(S3KeySensor): tsk_is_file_in_s3_available> on 2024-06-27 22:01:03.531556+00:00
[2024-06-27T22:01:12.971+0000] {standard_task_runner.py:63} INFO - Started process 5432 to run task
[2024-06-27T22:01:12.974+0000] {standard_task_runner.py:90} INFO - Running: ['airflow', 'tasks', 'run', 'zillow_analytics_dag', 'tsk_is_file_in_s3_available', 'manual__2024-06-27T22:01:03.531556+00:00', '--job-id', '21', '--raw', '--subdir', 'DAGS_FOLDER/zillowanalytics.py', '--cfg-path', '/tmp/tmpon6rvkyt']
[2024-06-27T22:01:12.975+0000] {standard_task_runner.py:91} INFO - Job 21: Subtask tsk_is_file_in_s3_available
[2024-06-27T22:01:13.011+0000] {task_command.py:426} INFO - Running <TaskInstance: zillow_analytics_dag.tsk_is_file_in_s3_available manual__2024-06-27T22:01:03.531556+00:00 [running]> on host ip-172-31-6-214.us-east-2.compute.internal
[2024-06-27T22:01:13.086+0000] {taskinstance.py:2648} INFO - Exporting env vars: AIRFLOW_CTX_DAG_EMAIL='myemail@domain.com' AIRFLOW_CTX_DAG_OWNER='airflow' AIRFLOW_CTX_DAG_ID='zillow_analytics_dag' AIRFLOW_CTX_TASK_ID='tsk_is_file_in_s3_available' AIRFLOW_CTX_EXECUTION_DATE='2024-06-27T22:01:03.531556+00:00' AIRFLOW_CTX_TRY_NUMBER='1' AIRFLOW_CTX_DAG_RUN_ID='manual__2024-06-27T22:01:03.531556+00:00'
[2024-06-27T22:01:13.087+0000] {taskinstance.py:430} INFO - ::endgroup::
[2024-06-27T22:01:13.099+0000] {baseoperator.py:400} WARNING - S3KeySensor.execute cannot be called outside TaskInstance!
[2024-06-27T22:01:13.100+0000] {s3.py:117} INFO - Poking for key : s3://clean-data-csv-bucket/response_data_27062024220106.csv
[2024-06-27T22:01:13.105+0000] {base.py:84} INFO - Using connection ID 'aws_s3_conn' for task execution.
[2024-06-27T22:01:13.106+0000] {connection_wrapper.py:384} INFO - AWS Connection (conn_id='aws_s3_conn', conn_type='aws') credentials retrieved from login and password.
[2024-06-27T22:01:18.510+0000] {s3.py:117} INFO - Poking for key : s3://clean-data-csv-bucket/response_data_27062024220106.csv
[2024-06-27T22:01:23.519+0000] {s3.py:117} INFO - Poking for key : s3://clean-data-csv-bucket/response_data_27062024220106.csv
[2024-06-27T22:01:28.531+0000] {s3.py:117} INFO - Poking for key : s3://clean-data-csv-bucket/response_data_27062024220106.csv
[2024-06-27T22:01:33.542+0000] {s3.py:117} INFO - Poking for key : s3://clean-data-csv-bucket/response_data_27062024220106.csv
[2024-06-27T22:01:38.551+0000] {s3.py:117} INFO - Poking for key : s3://clean-data-csv-bucket/response_data_27062024220106.csv
[2024-06-27T22:01:43.562+0000] {s3.py:117} INFO - Poking for key : s3://clean-data-csv-bucket/response_data_27062024220106.csv
[2024-06-27T22:01:48.573+0000] {s3.py:117} INFO - Poking for key : s3://clean-data-csv-bucket/response_data_27062024220106.csv
[2024-06-27T22:01:53.583+0000] {s3.py:117} INFO - Poking for key : s3://clean-data-csv-bucket/response_data_27062024220106.csv
[2024-06-27T22:01:58.594+0000] {s3.py:117} INFO - Poking for key : s3://clean-data-csv-bucket/response_data_27062024220106.csv
[2024-06-27T22:02:03.604+0000] {s3.py:117} INFO - Poking for key : s3://clean-data-csv-bucket/response_data_27062024220106.csv
[2024-06-27T22:02:08.615+0000] {s3.py:117} INFO - Poking for key : s3://clean-data-csv-bucket/response_data_27062024220106.csv
[2024-06-27T22:02:13.626+0000] {s3.py:117} INFO - Poking for key : s3://clean-data-csv-bucket/response_data_27062024220106.csv
[2024-06-27T22:02:13.636+0000] {taskinstance.py:441} INFO - ::group::Post task execution logs
[2024-06-27T22:02:13.637+0000] {taskinstance.py:2905} ERROR - Task failed with exception
Traceback (most recent call last):
  File "/home/ubuntu/venv/lib/python3.12/site-packages/airflow/models/taskinstance.py", line 465, in _execute_task
    result = _execute_callable(context=context, **execute_callable_kwargs)
             ^^^^^^^^^^^^^^^^^^^^^^^^^^^^^^^^^^^^^^^^^^^^^^^^^^^^^^^^^^^^^
  File "/home/ubuntu/venv/lib/python3.12/site-packages/airflow/models/taskinstance.py", line 432, in _execute_callable
    return execute_callable(context=context, **execute_callable_kwargs)
           ^^^^^^^^^^^^^^^^^^^^^^^^^^^^^^^^^^^^^^^^^^^^^^^^^^^^^^^^^^^^
  File "/home/ubuntu/venv/lib/python3.12/site-packages/airflow/models/baseoperator.py", line 401, in wrapper
    return func(self, *args, **kwargs)
           ^^^^^^^^^^^^^^^^^^^^^^^^^^^
  File "/home/ubuntu/venv/lib/python3.12/site-packages/airflow/providers/amazon/aws/sensors/s3.py", line 183, in execute
    super().execute(context)
  File "/home/ubuntu/venv/lib/python3.12/site-packages/airflow/models/baseoperator.py", line 401, in wrapper
    return func(self, *args, **kwargs)
           ^^^^^^^^^^^^^^^^^^^^^^^^^^^
  File "/home/ubuntu/venv/lib/python3.12/site-packages/airflow/sensors/base.py", line 281, in execute
    raise AirflowSensorTimeout(message)
airflow.exceptions.AirflowSensorTimeout: Sensor has timed out; run duration of 60.53656112999988 seconds exceeds the specified timeout of 60.0.
[2024-06-27T22:02:13.641+0000] {taskinstance.py:1206} INFO - Immediate failure requested. Marking task as FAILED. dag_id=zillow_analytics_dag, task_id=tsk_is_file_in_s3_available, run_id=manual__2024-06-27T22:01:03.531556+00:00, execution_date=20240627T220103, start_date=20240627T220112, end_date=20240627T220213
[2024-06-27T22:02:13.652+0000] {standard_task_runner.py:110} ERROR - Failed to execute job 21 for task tsk_is_file_in_s3_available (Sensor has timed out; run duration of 60.53656112999988 seconds exceeds the specified timeout of 60.0.; 5432)
[2024-06-27T22:02:13.661+0000] {local_task_job_runner.py:240} INFO - Task exited with return code 1
[2024-06-27T22:02:13.669+0000] {taskinstance.py:3503} INFO - 0 downstream tasks scheduled from follow-on schedule check
[2024-06-27T22:02:13.670+0000] {local_task_job_runner.py:222} INFO - ::endgroup::
