[2024-06-27T21:28:11.975+0000] {local_task_job_runner.py:120} INFO - ::group::Pre task execution logs
[2024-06-27T21:28:11.993+0000] {taskinstance.py:2076} INFO - Dependencies all met for dep_context=non-requeueable deps ti=<TaskInstance: zillow_analytics_dag.tsk_load_to_s3 manual__2024-06-27T21:28:01.117444+00:00 [queued]>
[2024-06-27T21:28:11.999+0000] {taskinstance.py:2076} INFO - Dependencies all met for dep_context=requeueable deps ti=<TaskInstance: zillow_analytics_dag.tsk_load_to_s3 manual__2024-06-27T21:28:01.117444+00:00 [queued]>
[2024-06-27T21:28:11.999+0000] {taskinstance.py:2306} INFO - Starting attempt 1 of 3
[2024-06-27T21:28:12.017+0000] {taskinstance.py:2330} INFO - Executing <Task(BashOperator): tsk_load_to_s3> on 2024-06-27 21:28:01.117444+00:00
[2024-06-27T21:28:12.021+0000] {standard_task_runner.py:63} INFO - Started process 3783 to run task
[2024-06-27T21:28:12.024+0000] {standard_task_runner.py:90} INFO - Running: ['airflow', 'tasks', 'run', 'zillow_analytics_dag', 'tsk_load_to_s3', 'manual__2024-06-27T21:28:01.117444+00:00', '--job-id', '6', '--raw', '--subdir', 'DAGS_FOLDER/zillowanalytics.py', '--cfg-path', '/tmp/tmpl97zvz31']
[2024-06-27T21:28:12.026+0000] {standard_task_runner.py:91} INFO - Job 6: Subtask tsk_load_to_s3
[2024-06-27T21:28:12.060+0000] {task_command.py:426} INFO - Running <TaskInstance: zillow_analytics_dag.tsk_load_to_s3 manual__2024-06-27T21:28:01.117444+00:00 [running]> on host ip-172-31-6-214.us-east-2.compute.internal
[2024-06-27T21:28:12.129+0000] {taskinstance.py:2648} INFO - Exporting env vars: AIRFLOW_CTX_DAG_EMAIL='myemail@domain.com' AIRFLOW_CTX_DAG_OWNER='airflow' AIRFLOW_CTX_DAG_ID='zillow_analytics_dag' AIRFLOW_CTX_TASK_ID='tsk_load_to_s3' AIRFLOW_CTX_EXECUTION_DATE='2024-06-27T21:28:01.117444+00:00' AIRFLOW_CTX_TRY_NUMBER='1' AIRFLOW_CTX_DAG_RUN_ID='manual__2024-06-27T21:28:01.117444+00:00'
[2024-06-27T21:28:12.129+0000] {taskinstance.py:430} INFO - ::endgroup::
[2024-06-27T21:28:12.142+0000] {subprocess.py:63} INFO - Tmp dir root location: /tmp
[2024-06-27T21:28:12.142+0000] {subprocess.py:75} INFO - Running command: ['/usr/bin/bash', '-c', 'aws s3 mv /home/ubuntu/response_data_27062024212806.json s3://zillow-etl-bucket/']
[2024-06-27T21:28:12.149+0000] {subprocess.py:86} INFO - Output:
[2024-06-27T21:28:12.670+0000] {subprocess.py:93} INFO - move failed: ../../home/ubuntu/response_data_27062024212806.json to s3://zillow-etl-bucket/response_data_27062024212806.json Unable to locate credentials
[2024-06-27T21:28:12.747+0000] {subprocess.py:97} INFO - Command exited with return code 1
[2024-06-27T21:28:12.748+0000] {taskinstance.py:441} INFO - ::group::Post task execution logs
[2024-06-27T21:28:12.754+0000] {taskinstance.py:2905} ERROR - Task failed with exception
Traceback (most recent call last):
  File "/home/ubuntu/venv/lib/python3.12/site-packages/airflow/models/taskinstance.py", line 465, in _execute_task
    result = _execute_callable(context=context, **execute_callable_kwargs)
             ^^^^^^^^^^^^^^^^^^^^^^^^^^^^^^^^^^^^^^^^^^^^^^^^^^^^^^^^^^^^^
  File "/home/ubuntu/venv/lib/python3.12/site-packages/airflow/models/taskinstance.py", line 432, in _execute_callable
    return execute_callable(context=context, **execute_callable_kwargs)
           ^^^^^^^^^^^^^^^^^^^^^^^^^^^^^^^^^^^^^^^^^^^^^^^^^^^^^^^^^^^^
  File "/home/ubuntu/venv/lib/python3.12/site-packages/airflow/models/baseoperator.py", line 401, in wrapper
    return func(self, *args, **kwargs)
           ^^^^^^^^^^^^^^^^^^^^^^^^^^^
  File "/home/ubuntu/venv/lib/python3.12/site-packages/airflow/operators/bash.py", line 243, in execute
    raise AirflowException(
airflow.exceptions.AirflowException: Bash command failed. The command returned a non-zero exit code 1.
[2024-06-27T21:28:12.758+0000] {taskinstance.py:1206} INFO - Marking task as UP_FOR_RETRY. dag_id=zillow_analytics_dag, task_id=tsk_load_to_s3, run_id=manual__2024-06-27T21:28:01.117444+00:00, execution_date=20240627T212801, start_date=20240627T212811, end_date=20240627T212812
[2024-06-27T21:28:12.771+0000] {standard_task_runner.py:110} ERROR - Failed to execute job 6 for task tsk_load_to_s3 (Bash command failed. The command returned a non-zero exit code 1.; 3783)
[2024-06-27T21:28:12.798+0000] {local_task_job_runner.py:240} INFO - Task exited with return code 1
[2024-06-27T21:28:12.810+0000] {taskinstance.py:3503} INFO - 0 downstream tasks scheduled from follow-on schedule check
[2024-06-27T21:28:12.810+0000] {local_task_job_runner.py:222} INFO - ::endgroup::
