[2024-06-27T21:33:01.061+0000] {local_task_job_runner.py:120} INFO - ::group::Pre task execution logs
[2024-06-27T21:33:01.081+0000] {taskinstance.py:2076} INFO - Dependencies all met for dep_context=non-requeueable deps ti=<TaskInstance: zillow_analytics_dag.tsk_load_to_s3 manual__2024-06-27T21:32:20.297763+00:00 [queued]>
[2024-06-27T21:33:01.087+0000] {taskinstance.py:2076} INFO - Dependencies all met for dep_context=requeueable deps ti=<TaskInstance: zillow_analytics_dag.tsk_load_to_s3 manual__2024-06-27T21:32:20.297763+00:00 [queued]>
[2024-06-27T21:33:01.087+0000] {taskinstance.py:2306} INFO - Starting attempt 3 of 3
[2024-06-27T21:33:01.102+0000] {taskinstance.py:2330} INFO - Executing <Task(BashOperator): tsk_load_to_s3> on 2024-06-27 21:32:20.297763+00:00
[2024-06-27T21:33:01.107+0000] {standard_task_runner.py:63} INFO - Started process 4116 to run task
[2024-06-27T21:33:01.110+0000] {standard_task_runner.py:90} INFO - Running: ['airflow', 'tasks', 'run', 'zillow_analytics_dag', 'tsk_load_to_s3', 'manual__2024-06-27T21:32:20.297763+00:00', '--job-id', '14', '--raw', '--subdir', 'DAGS_FOLDER/zillowanalytics.py', '--cfg-path', '/tmp/tmp44_8t9yy']
[2024-06-27T21:33:01.111+0000] {standard_task_runner.py:91} INFO - Job 14: Subtask tsk_load_to_s3
[2024-06-27T21:33:01.149+0000] {task_command.py:426} INFO - Running <TaskInstance: zillow_analytics_dag.tsk_load_to_s3 manual__2024-06-27T21:32:20.297763+00:00 [running]> on host ip-172-31-6-214.us-east-2.compute.internal
[2024-06-27T21:33:01.213+0000] {taskinstance.py:2648} INFO - Exporting env vars: AIRFLOW_CTX_DAG_EMAIL='myemail@domain.com' AIRFLOW_CTX_DAG_OWNER='airflow' AIRFLOW_CTX_DAG_ID='zillow_analytics_dag' AIRFLOW_CTX_TASK_ID='tsk_load_to_s3' AIRFLOW_CTX_EXECUTION_DATE='2024-06-27T21:32:20.297763+00:00' AIRFLOW_CTX_TRY_NUMBER='3' AIRFLOW_CTX_DAG_RUN_ID='manual__2024-06-27T21:32:20.297763+00:00'
[2024-06-27T21:33:01.214+0000] {taskinstance.py:430} INFO - ::endgroup::
[2024-06-27T21:33:01.226+0000] {subprocess.py:63} INFO - Tmp dir root location: /tmp
[2024-06-27T21:33:01.227+0000] {subprocess.py:75} INFO - Running command: ['/usr/bin/bash', '-c', 'aws s3 mv /home/ubuntu/response_data_27062024213222.json s3://zillow-etl-bucket/']
[2024-06-27T21:33:01.234+0000] {subprocess.py:86} INFO - Output:
[2024-06-27T21:33:01.777+0000] {subprocess.py:93} INFO - move failed: ../../home/ubuntu/response_data_27062024213222.json to s3://zillow-etl-bucket/response_data_27062024213222.json Unable to locate credentials
[2024-06-27T21:33:01.857+0000] {subprocess.py:97} INFO - Command exited with return code 1
[2024-06-27T21:33:01.858+0000] {taskinstance.py:441} INFO - ::group::Post task execution logs
[2024-06-27T21:33:01.865+0000] {taskinstance.py:2905} ERROR - Task failed with exception
Traceback (most recent call last):
  File "/home/ubuntu/venv/lib/python3.12/site-packages/airflow/models/taskinstance.py", line 465, in _execute_task
    result = _execute_callable(context=context, **execute_callable_kwargs)
             ^^^^^^^^^^^^^^^^^^^^^^^^^^^^^^^^^^^^^^^^^^^^^^^^^^^^^^^^^^^^^
  File "/home/ubuntu/venv/lib/python3.12/site-packages/airflow/models/taskinstance.py", line 432, in _execute_callable
    return execute_callable(context=context, **execute_callable_kwargs)
           ^^^^^^^^^^^^^^^^^^^^^^^^^^^^^^^^^^^^^^^^^^^^^^^^^^^^^^^^^^^^
  File "/home/ubuntu/venv/lib/python3.12/site-packages/airflow/models/baseoperator.py", line 401, in wrapper
    return func(self, *args, **kwargs)
           ^^^^^^^^^^^^^^^^^^^^^^^^^^^
  File "/home/ubuntu/venv/lib/python3.12/site-packages/airflow/operators/bash.py", line 243, in execute
    raise AirflowException(
airflow.exceptions.AirflowException: Bash command failed. The command returned a non-zero exit code 1.
[2024-06-27T21:33:01.868+0000] {taskinstance.py:1206} INFO - Marking task as FAILED. dag_id=zillow_analytics_dag, task_id=tsk_load_to_s3, run_id=manual__2024-06-27T21:32:20.297763+00:00, execution_date=20240627T213220, start_date=20240627T213301, end_date=20240627T213301
[2024-06-27T21:33:01.884+0000] {standard_task_runner.py:110} ERROR - Failed to execute job 14 for task tsk_load_to_s3 (Bash command failed. The command returned a non-zero exit code 1.; 4116)
[2024-06-27T21:33:01.924+0000] {local_task_job_runner.py:240} INFO - Task exited with return code 1
[2024-06-27T21:33:01.935+0000] {taskinstance.py:3503} INFO - 0 downstream tasks scheduled from follow-on schedule check
[2024-06-27T21:33:01.936+0000] {local_task_job_runner.py:222} INFO - ::endgroup::
