[2024-06-28T00:00:09.702+0000] {local_task_job_runner.py:120} INFO - ::group::Pre task execution logs
[2024-06-28T00:00:09.713+0000] {taskinstance.py:2076} INFO - Dependencies all met for dep_context=non-requeueable deps ti=<TaskInstance: zillow_analytics_dag.tsk_is_file_in_s3_available scheduled__2024-06-27T00:00:00+00:00 [queued]>
[2024-06-28T00:00:09.719+0000] {taskinstance.py:2076} INFO - Dependencies all met for dep_context=requeueable deps ti=<TaskInstance: zillow_analytics_dag.tsk_is_file_in_s3_available scheduled__2024-06-27T00:00:00+00:00 [queued]>
[2024-06-28T00:00:09.720+0000] {taskinstance.py:2306} INFO - Starting attempt 1 of 2
[2024-06-28T00:00:09.735+0000] {taskinstance.py:2330} INFO - Executing <Task(S3KeySensor): tsk_is_file_in_s3_available> on 2024-06-27 00:00:00+00:00
[2024-06-28T00:00:09.740+0000] {standard_task_runner.py:63} INFO - Started process 6184 to run task
[2024-06-28T00:00:09.743+0000] {standard_task_runner.py:90} INFO - Running: ['airflow', 'tasks', 'run', 'zillow_analytics_dag', 'tsk_is_file_in_s3_available', 'scheduled__2024-06-27T00:00:00+00:00', '--job-id', '63', '--raw', '--subdir', 'DAGS_FOLDER/zillowanalytics.py', '--cfg-path', '/tmp/tmper9_pq51']
[2024-06-28T00:00:09.745+0000] {standard_task_runner.py:91} INFO - Job 63: Subtask tsk_is_file_in_s3_available
[2024-06-28T00:00:09.784+0000] {task_command.py:426} INFO - Running <TaskInstance: zillow_analytics_dag.tsk_is_file_in_s3_available scheduled__2024-06-27T00:00:00+00:00 [running]> on host ip-172-31-6-214.us-east-2.compute.internal
[2024-06-28T00:00:09.862+0000] {taskinstance.py:2648} INFO - Exporting env vars: AIRFLOW_CTX_DAG_EMAIL='myemail@domain.com' AIRFLOW_CTX_DAG_OWNER='airflow' AIRFLOW_CTX_DAG_ID='zillow_analytics_dag' AIRFLOW_CTX_TASK_ID='tsk_is_file_in_s3_available' AIRFLOW_CTX_EXECUTION_DATE='2024-06-27T00:00:00+00:00' AIRFLOW_CTX_TRY_NUMBER='1' AIRFLOW_CTX_DAG_RUN_ID='scheduled__2024-06-27T00:00:00+00:00'
[2024-06-28T00:00:09.863+0000] {taskinstance.py:430} INFO - ::endgroup::
[2024-06-28T00:00:09.876+0000] {baseoperator.py:400} WARNING - S3KeySensor.execute cannot be called outside TaskInstance!
[2024-06-28T00:00:09.876+0000] {s3.py:117} INFO - Poking for key : s3://clean-data-csv-bucket/response_data_28062024000003.csv
[2024-06-28T00:00:09.882+0000] {base.py:84} INFO - Using connection ID 'aws_s3_conn' for task execution.
[2024-06-28T00:00:09.882+0000] {connection_wrapper.py:384} INFO - AWS Connection (conn_id='aws_s3_conn', conn_type='aws') credentials retrieved from login and password.
[2024-06-28T00:00:15.296+0000] {s3.py:117} INFO - Poking for key : s3://clean-data-csv-bucket/response_data_28062024000003.csv
[2024-06-28T00:00:20.306+0000] {s3.py:117} INFO - Poking for key : s3://clean-data-csv-bucket/response_data_28062024000003.csv
[2024-06-28T00:00:25.317+0000] {s3.py:117} INFO - Poking for key : s3://clean-data-csv-bucket/response_data_28062024000003.csv
[2024-06-28T00:00:30.328+0000] {s3.py:117} INFO - Poking for key : s3://clean-data-csv-bucket/response_data_28062024000003.csv
[2024-06-28T00:00:35.338+0000] {s3.py:117} INFO - Poking for key : s3://clean-data-csv-bucket/response_data_28062024000003.csv
[2024-06-28T00:00:40.349+0000] {s3.py:117} INFO - Poking for key : s3://clean-data-csv-bucket/response_data_28062024000003.csv
[2024-06-28T00:00:45.360+0000] {s3.py:117} INFO - Poking for key : s3://clean-data-csv-bucket/response_data_28062024000003.csv
[2024-06-28T00:00:50.372+0000] {s3.py:117} INFO - Poking for key : s3://clean-data-csv-bucket/response_data_28062024000003.csv
[2024-06-28T00:00:55.383+0000] {s3.py:117} INFO - Poking for key : s3://clean-data-csv-bucket/response_data_28062024000003.csv
[2024-06-28T00:01:00.396+0000] {s3.py:117} INFO - Poking for key : s3://clean-data-csv-bucket/response_data_28062024000003.csv
[2024-06-28T00:01:05.407+0000] {s3.py:117} INFO - Poking for key : s3://clean-data-csv-bucket/response_data_28062024000003.csv
[2024-06-28T00:01:10.418+0000] {s3.py:117} INFO - Poking for key : s3://clean-data-csv-bucket/response_data_28062024000003.csv
[2024-06-28T00:01:10.428+0000] {taskinstance.py:441} INFO - ::group::Post task execution logs
[2024-06-28T00:01:10.428+0000] {taskinstance.py:2905} ERROR - Task failed with exception
Traceback (most recent call last):
  File "/home/ubuntu/venv/lib/python3.12/site-packages/airflow/models/taskinstance.py", line 465, in _execute_task
    result = _execute_callable(context=context, **execute_callable_kwargs)
             ^^^^^^^^^^^^^^^^^^^^^^^^^^^^^^^^^^^^^^^^^^^^^^^^^^^^^^^^^^^^^
  File "/home/ubuntu/venv/lib/python3.12/site-packages/airflow/models/taskinstance.py", line 432, in _execute_callable
    return execute_callable(context=context, **execute_callable_kwargs)
           ^^^^^^^^^^^^^^^^^^^^^^^^^^^^^^^^^^^^^^^^^^^^^^^^^^^^^^^^^^^^
  File "/home/ubuntu/venv/lib/python3.12/site-packages/airflow/models/baseoperator.py", line 401, in wrapper
    return func(self, *args, **kwargs)
           ^^^^^^^^^^^^^^^^^^^^^^^^^^^
  File "/home/ubuntu/venv/lib/python3.12/site-packages/airflow/providers/amazon/aws/sensors/s3.py", line 183, in execute
    super().execute(context)
  File "/home/ubuntu/venv/lib/python3.12/site-packages/airflow/models/baseoperator.py", line 401, in wrapper
    return func(self, *args, **kwargs)
           ^^^^^^^^^^^^^^^^^^^^^^^^^^^
  File "/home/ubuntu/venv/lib/python3.12/site-packages/airflow/sensors/base.py", line 281, in execute
    raise AirflowSensorTimeout(message)
airflow.exceptions.AirflowSensorTimeout: Sensor has timed out; run duration of 60.55192953900041 seconds exceeds the specified timeout of 60.0.
[2024-06-28T00:01:10.433+0000] {taskinstance.py:1206} INFO - Immediate failure requested. Marking task as FAILED. dag_id=zillow_analytics_dag, task_id=tsk_is_file_in_s3_available, run_id=scheduled__2024-06-27T00:00:00+00:00, execution_date=20240627T000000, start_date=20240628T000009, end_date=20240628T000110
[2024-06-28T00:01:10.445+0000] {standard_task_runner.py:110} ERROR - Failed to execute job 63 for task tsk_is_file_in_s3_available (Sensor has timed out; run duration of 60.55192953900041 seconds exceeds the specified timeout of 60.0.; 6184)
[2024-06-28T00:01:10.483+0000] {local_task_job_runner.py:240} INFO - Task exited with return code 1
[2024-06-28T00:01:10.501+0000] {taskinstance.py:3503} INFO - 0 downstream tasks scheduled from follow-on schedule check
[2024-06-28T00:01:10.509+0000] {local_task_job_runner.py:222} INFO - ::endgroup::
